<?xml version="1.0" ?>
<mujoco model="template">
    <!--Credits from original OpenSim model: A reduced 3D gait model with 14 degrees of freedom and 22 muscles (based on planar gait9dof18 by Ajay Seth). Adjusted by Carmichael Ong to follow muscle strengths of Handsfield/Rajagopal and changed hamstrings to follow semimembranosus and to adjust passive curves of hamstrings, rect_fem, and vasti. Closely based on Delp S.L., Loan J.P., Hoy M.G., Zajac F.E., Topp E.L., Rosen J.M., Thelen D.G., Anderson F.C., Seth A. Notes: 3D, 23 DOF gait model created by D.G. Thelen, Univ. of Wisconsin-Madison, and Ajay Seth, Frank C. Anderson, and Scott L. Delp, Stanford University. Lower extremity joint defintions based on Delp et al. (1990). Low back joint and anthropometry based on Anderson and Pandy (1999, 2001). Planar knee model of Yamaguchi and Zajac (1989). Seth replaced tibia translation constraints with a CustomJoint for the knee and removed the patella to eliminate all kinematic constraints; insertions of the quadrucepts are handled with moving points in the tibia frame as defined by Delp 1990. Number of muscles was reduced by Anderson to improve simulation speed for demonstrations and is not intended to be used in research. License: Creative Commons (CCBY 3.0). You are free to distribute, remix, tweak, and build upon this work, even commercially, as long as you credit us for the original creation. http://creativecommons.org/licenses/by/3.0/ More Information: http://simtk-confluence.stanford.edu:8080/display/OpenSim/Gait+2392+and+2354+Models-->
	<!--Link changed (10 Aug 2023): https://simtk-confluence.stanford.edu:8443/display/OpenSim/Gait+2392+and+2354+Models-->
	<!-- Modifications: Chun Kwang Tan (cktan.neumove@gmail.com)
		1. Ankle joint angle ROM (range-of-movment) is modified to follow the ankle ranges of MyoLeg model (0.52 XML)
		2. Talus and Tibia distances are modified from 0.43 -> 0.4
		3. Joint angle ranges -> Following Matlab range from Reflex Controller
		4. Copied all muscle parameters from Left leg to Right leg.
			a. Tested the params with Standing posture, Left has lesser passive muscle forces in a standing posture.
		5. Added foot sensors for GRF measurements
		6. Locked lumbar extension joint to 0 deg
		7. Removed non-saggittal plane joints
	-->

    <!-- Modifications: Calder Robbins (robbins.cal@northeastern.edu)
    1. Added toes to the model, including the mtp joints.
    2. Added Extensor Digitorum Longus (EDL) and Flexor Digitorum Longus (FDL) muscles to both legs.
    3. Added non-actuated arms to the model.
    4. Minor adjustments to the inertial properties of the calcaneus bodies.
	-->


    <compiler angle="radian"/>
    <option timestep="0.001"> 
	  <flag warmstart="disable"/>
	</option>
    <size nconmax="400" njmax="1000" nkey="1" nuser_jnt="1"/>
    <visual>
        <scale framelength="0.5" framewidth="0.01"/>
        <global offwidth="1920" offheight="1080"/>
    </visual>
    <default class="main">
        <joint armature="1e-05" damping="0.05" limited="true"/>
        <geom margin="0.001" rgba="0.8 0.6 0.4 1"/>
        <site size="0.001 0.005 0.005"/>
        <tendon rgba="0.95 0.3 0.3 1" width="0.005"/>
        <default class="muscle">
            <general biasprm="0.75 1.05 -1 200 0.5 1.6 1.5 1.3 1.2 0" biastype="muscle" ctrllimited="true" ctrlrange="0 1" dynprm="0.01 0.04 0 0 0 0 0 0 0 0" dyntype="muscle" gainprm="0.75 1.05 -1 200 0.5 1.6 1.5 1.3 1.2 0" gaintype="muscle"/>
        </default>
        <default class="motor">
            <general gainprm="5 0 0 0 0 0 0 0 0 0"/>
        </default>
		<default class="myo_leg_touch">
			<site type="box" group="3" rgba="0.8 0.2 .2 .4"/>
		</default>
    </default>

    <asset>        
        <!-- Human -->
        <mesh file="../mesh/sacrum.stl" name="pelvis_geom_1_sacrum"/>
        <mesh file="../mesh/r_pelvis.stl" name="pelvis_geom_2_pelvis"/>
        <mesh file="../mesh/l_pelvis.stl" name="pelvis_geom_3_l_pelvis"/>
        <mesh file="../mesh/r_femur.stl" name="femur_r_geom_1_femur"/>
        <mesh file="../mesh/r_tibia.stl" name="tibia_r_geom_1_tibia"/>
        <mesh file="../mesh/r_fibula.stl" name="tibia_r_geom_2_fibula"/>
        <mesh file="../mesh/r_talus.stl" name="talus_r_geom_1_talus"/>
        <mesh file="../mesh/r_foot.stl" name="calcn_r_geom_1_foot"/>
        <mesh file="../mesh/r_bofoot.stl" name="toes_r_geom_1_bofoot"/>
        <mesh file="../mesh/l_femur.stl" name="femur_l_geom_1_l_femur"/>
        <mesh file="../mesh/l_tibia.stl" name="tibia_l_geom_1_l_tibia"/>
        <mesh file="../mesh/l_fibula.stl" name="tibia_l_geom_2_l_fibula"/>
        <mesh file="../mesh/l_talus.stl" name="talus_l_geom_1_l_talus"/>
        <mesh file="../mesh/l_foot.stl" name="calcn_l_geom_1_l_foot"/>
        <mesh file="../mesh/l_bofoot.stl" name="toes_l_geom_1_l_bofoot"/>
        <mesh file="../mesh/hat_spine.stl" name="torso_geom_1_hat_spine"/>
        <mesh file="../mesh/hat_jaw.stl" name="torso_geom_2_hat_jaw"/>
        <mesh file="../mesh/hat_skull.stl" name="torso_geom_3_hat_skull"/>
        <mesh file="../mesh/hat_ribs.stl" name="torso_geom_4_hat_ribs"/>

        <mesh file="../mesh/r_clavicle.stl" name="r_clavicle"/>
        <mesh file="../mesh/r_scapula.stl" name="r_scapula"/>
        <mesh file="../mesh/r_humerus.stl" name="r_humerus"/>
        <mesh file="../mesh/r_radius.stl" name="r_radius"/>
        <mesh file="../mesh/r_ulna.stl" name="r_ulna"/>
        <mesh file="../mesh/r_hand.stl" name="r_hand"/>
        
        <mesh file="../mesh/l_clavicle.stl" name="l_clavicle"/>
        <mesh file="../mesh/l_scapula.stl" name="l_scapula"/>
        <mesh file="../mesh/l_humerus.stl" name="l_humerus"/>
        <mesh file="../mesh/l_radius.stl" name="l_radius"/>
        <mesh file="../mesh/l_ulna.stl" name="l_ulna"/>
        <mesh file="../mesh/l_hand.stl" name="l_hand"/>
    </asset>
    
    <statistic center="0 0 0.6" extent="2.5"/>

	<visual>
        <scale framelength="0.5" framewidth="0.01"/>
        <global offwidth="1920" offheight="1080" elevation="0.0" azimuth="90.0"/>
        <headlight ambient="0.1 0.1 0.1" diffuse="0.4 0.4 0.4" specular="0.5 0.5 0.5"/>
    </visual>
    
    <include file="../terrain_config.xml"/>

    <worldbody>
        <camera name="side_view" pos="-3 0 1.5" xyaxes="0 -1 0 1 0 2" mode="trackcom"/>
        <camera name="front_view" pos="0 -3 1.5" xyaxes="1 0 0 0 1 2" mode="trackcom"/>
        <camera name="topview" pos="0 -10.5 15" euler="+0.8 -0.8 0" mode="fixed"/>
        <camera name="view" pos="-1.5 -5 1.8" euler="+1.37 -0.1 0" mode="fixed"/>
		<camera name="slope_view" pos="0 -4.0 0.8" euler="1.3 0.0 0.0" mode="trackcom"/>
		<camera name="slope_front_view" pos="3 0 1.25" xyaxes="0 1 0 -1 0 2" mode="trackcom"/>

		<site name="pelvis_target" size="0.02" pos="0 0 .92" group="4"/>
        <body name="pelvis" pos="0 0 0" quat="0.707035 0.707179 0 0">
			<site name="pelvis" size="0.02" group="4"/>
            <inertial diaginertia="0.1028 0.0871 0.0579" mass="11.777" pos="-0.0707 0 0"/>
            <joint axis="1 0 0" damping="0" name="pelvis_tx" pos="0 0 0" limited="false" type="slide"/>
            <joint axis="0 1 0" damping="0" name="pelvis_ty"  pos="0 0 0" limited="false" type="slide"/>
            <joint axis="0 0 1" damping="0" name="pelvis_tz" pos="0 0 0" limited="false" type="slide"/>
            <joint axis="0 0 1" damping="0" name="pelvis_tilt" pos="0 0 0" limited="false" />
            <joint axis="1 0 0" damping="0" name="pelvis_list" pos="0 0 0" limited="false"/>
            <joint axis="0 1 0" damping="0" name="pelvis_rotation" pos="0 0 0" limited="false"/>
            <geom mesh="pelvis_geom_1_sacrum" name="pelvis_geom_1" rgba="1 1 1 1" type="mesh"/>
            <geom mesh="pelvis_geom_2_pelvis" name="pelvis_geom_2" rgba="1 1 1 1" type="mesh"/>
            <geom mesh="pelvis_geom_3_l_pelvis" name="pelvis_geom_3" rgba="1 1 1 1" type="mesh"/>
            <site name="abd_r_glut_med2_r-P1" pos="-0.0855 0.0445 0.0766"/>
            <site name="add_r_add_mag1_r-P1" pos="-0.0732 -0.1174 0.0255"/>
            <site name="hamstrings_r_semimem_r-P1" pos="-0.1192 -0.09747 0.07151"/>
            <site name="glut_max_r_glut_max2_r-P1" pos="-0.1349 0.0176 0.0563"/>
            <site name="glut_max_r_glut_max2_r-P2" pos="-0.1376 -0.052 0.0914"/>
            <site name="iliopsoas_r_psoas_r-P1" pos="-0.0647 0.0887 0.0289"/>
            <site name="iliopsoas_r_psoas_r-P2" pos="-0.0238 -0.057 0.0759"/>
            <site name="rect_fem_r_rect_fem_r-P1" pos="-0.0295 -0.0311 0.0968"/>
            <site name="abd_l_glut_med2_l-P1" pos="-0.0855 0.0445 -0.0766"/>
            <site name="add_l_add_mag1_l-P1" pos="-0.0732 -0.1174 -0.0255"/>
            <site name="hamstrings_l_semimem_l-P1" pos="-0.1192 -0.09747 -0.07151"/>
            <site name="glut_max_l_glut_max2_l-P1" pos="-0.1349 0.0176 -0.0563"/>
            <site name="glut_max_l_glut_max2_l-P2" pos="-0.1376 -0.052 -0.0914"/>
            <site name="iliopsoas_l_psoas_l-P1" pos="-0.0647 0.0887 -0.0289"/>
            <site name="iliopsoas_l_psoas_l-P2" pos="-0.0238 -0.057 -0.0759"/>
            <site name="rect_fem_l_rect_fem_l-P1" pos="-0.0295 -0.0311 -0.0968"/>

            <body name="femur_r" pos="-0.0707 -0.0661 0.0835">
                <inertial diaginertia="0.1412 0.145 0.0351" mass="9.3014" pos="0 -0.2 0" quat="0.5 0.5 -0.5 0.5"/>
                <joint axis="0 0 1" name="hip_flexion_r" pos="0 0 0" range="-0.349 2.356"/>
                <joint axis="1 0 0" name="hip_adduction_r" pos="0 0 0" range="-0.873 0.524"/>
                <joint axis="0 1 0" name="hip_rotation_r" pos="0 0 0" range="-0.698 0.698"/>
                <geom mesh="femur_r_geom_1_femur" name="femur_r_geom_1" rgba="1 1 1 1" type="mesh"/>
                <site name="abd_r_glut_med2_r-P2" pos="-0.0258 -0.0058 0.0527"/>
                <site name="add_r_add_mag1_r-P2" pos="-0.0045 -0.1211 0.0339"/>
                <site name="bifemsh_r_bifemsh_r-P1" pos="0.005 -0.2111 0.0234"/>
                <site name="glut_max_r_glut_max2_r-P3" pos="-0.0426 -0.053 0.0293"/>
                <site name="glut_max_r_glut_max2_r-P4" pos="-0.0156 -0.1016 0.0419"/>
                <site name="iliopsoas_r_psoas_r-P4" pos="0.0016 -0.0507 0.0038"/>
                <site name="iliopsoas_r_psoas_r-P5" pos="-0.0188 -0.0597 0.0104"/>
                <site name="vasti_r_vas_int_r-P1" pos="0.029 -0.1924 0.031"/>
                <site name="vasti_r_vas_int_r-P2" pos="0.0335 -0.2084 0.0285"/>
                <site name="vasti_r_vas_int_r-P3" pos="0.048 -0.35 0.0055"/>
                <site name="gastroc_r_med_gas_r-P1" pos="-0.019 -0.3929 -0.0235"/>
                <site name="rect_fem_r_rect_fem_r-P2" pos="0.048 -0.35 -0.0055"/>
                 
                <body name="tibia_r" pos="0 0 0">
                    <inertial diaginertia="0.0511 0.0504 0.0051" mass="3.7075" pos="0 -0.1867 0" quat="0.5 0.5 -0.5 0.5"/>
                    <joint axis="1 0 0" name="knee_r_translation1" pos="0 0 0" range="-0.005574 0.00411" type="slide"/>
                    <joint axis="0 1 0" name="knee_r_translation2" pos="0 0 0" range="-0.4226 -0.3953" type="slide"/>
                    <joint axis="0 0 1" name="knee_angle_r" pos="0 0 0" range="-2.531 0.0"/>
                    <geom mesh="tibia_r_geom_1_tibia" name="tibia_r_geom_1" rgba="1 1 1 1" type="mesh"/>
                    <geom mesh="tibia_r_geom_2_fibula" name="tibia_r_geom_2" rgba="1 1 1 1" type="mesh"/>
                    <site name="hamstrings_r_semimem_r-P3" pos="-0.027 -0.04771 -0.01957"/>
                    <site name="bifemsh_r_bifemsh_r-P2" pos="-0.0301 -0.036 0.02943"/>
                    <site name="bifemsh_r_bifemsh_r-P3" pos="-0.0234 -0.0563 0.0343"/>
                    <site name="soleus_r_soleus_r-P1" pos="-0.0024 -0.1533 0.0071"/>
                    <site name="tib_ant_r_tib_ant_r-P1" pos="0.0179 -0.1624 0.0115"/>
                    <site name="tib_ant_r_tib_ant_r-P2" pos="0.0329 -0.3951 -0.0177"/>
                    <site name="edl_r-P1" pos="-0.016 -0.1157 0.0205"/>
                    <site name="edl_r-P2" pos="0.0164 -0.376 0.0112"/>
                    <site name="fdl_r-P1" pos="-0.0023 -0.1832 -0.0018"/>
                    <site name="fdl_r-P2" pos="-0.0176 -0.3645 -0.0124"/>
                    
                    <body name="talus_r" pos="0 -0.40 0">
                        <inertial diaginertia="0.0001 0.0001 0.0001" mass="0.1" pos="0 0 0"/>
                        <joint axis="0 0 1" name="ankle_angle_r" pos="0 0 0" range="-1.134 0.349"/>
                        <geom mesh="talus_r_geom_1_talus" name="talus_r_geom_1" rgba="1 1 1 1" type="mesh"/>

                        <body name="calcn_r" pos="-0.04877 -0.04195 0.00792">
                            <inertial diaginertia="0.00041 0.00039 0.00014" mass="1.25" pos="0.1 0.03 0" quat="0 0.707107 0 0.707107"/>
                            <geom mesh="calcn_r_geom_1_foot" name="calcn_r_geom_1" rgba="1 1 1 1" type="mesh"/>
                            <site name="gastroc_r_med_gas_r-P3" pos="0 0.031 -0.0053"/>
                            <site name="soleus_r_soleus_r-P2" pos="0 0.031 -0.0053"/>
                            <site name="tib_ant_r_tib_ant_r-P3" pos="0.1166 0.0178 -0.0305"/>
                            <site name="edl_r-P3" pos="0.0919 0.036 0.0008"/>
                            <site name="edl_r-P4" pos="0.1616 0.0055 0.013"/>
                            <site name="fdl_r-P3" pos="0.0436 0.0315 -0.028"/>
                            <site name="fdl_r-P4" pos="0.0708 0.0176 -0.0263"/>
                            <site name="fdl_r-P5" pos="0.1658 -0.0081 0.0116"/>
                            
                            <site name="r_foot_touch" type="box" pos="0.01 -0.002 -0.01" size=".03 .02 .03" euler="0 0 0" class="myo_leg_touch"/>
                            <site name="r_heel_btm" type="sphere" pos="0.01 -0.008 -0.01" size="0.01" group="3" rgba="0 1 0 0.4"/>
                            <site name="r_toe_btm" type="sphere" pos="0.17 -0.003 -0.01" size="0.01" group="3" rgba="0 1 0 0.4" euler="0 0 0.1"/>
                            
                            <body name="toes_r" pos="0.1788 -0.002 0.00108">
                                <inertial diaginertia="0.0001 0.0001 0.0001" mass="0.2166" pos="0.0346 0.006 -0.0175" quat="0.707107 0 0 0.707107"/>
                                <joint axis="0 0 1" name="mtp_angle_r" damping= "0.5" pos="0 0 0" range="-0.523599 0.523599"/>
                                <site name="edl_r-P5" pos="0.0003 0.0047 0.0153"/>
                                <site name="edl_r-P6" pos="0.0443 -0.0004 0.025"/>
                                <site name="fdl_r-P6" pos="-0.0019 -0.0078 0.0147"/>
                                <site name="fdl_r-P7" pos="0.0285 -0.0071 0.0215"/>
                                <site name="fdl_r-P8" pos="0.0441 -0.006 0.0242"/>

                                <geom mesh="toes_r_geom_1_bofoot" name="toes_r_geom_1" rgba="1 1 1 1" type="mesh"/>
                                <site name="r_toes_touch" type="box" pos="0.0 -0.002 0.01" size=".05 .025 .075" euler="0 1.5 0" class="myo_leg_touch"/>
                            </body>
                        </body>
                    </body>

                    <body name="hamstrings_r_semimem_r-P2" pos="0 0 -0.01957">
                        <inertial diaginertia="0.00000001 0.00000001 0.00000001" mass="0.001" pos="0 0 -0.01957"/>
                        <joint axis="1 0 0" name="hamstrings_r_semimem_r-P2_x" pos="0 0 0" range="-0.0348 -0.027" type="slide"/>
                        <joint axis="0 1 0" name="hamstrings_r_semimem_r-P2_y" pos="0 0 0" range="-0.04771 -0.03519" type="slide"/>
                        <site name="hamstrings_r_semimem_r-P2" pos="0 0 0"/>
                    </body>
                    <body name="rect_fem_r_rect_fem_r-P3" pos="0 0 0.001399">
                        <inertial diaginertia="0.00000001 0.00000001 0.00000001" mass="0.001" pos="0 0 0.001399"/>
                        <joint axis="1 0 0" name="rect_fem_r_rect_fem_r-P3_x" pos="0 0 0" range="0.01558 0.0733" type="slide"/>
                        <joint axis="0 1 0" name="rect_fem_r_rect_fem_r-P3_y" pos="0 0 0" range="-0.06738 0.02531" type="slide"/>
                        <site name="rect_fem_r_rect_fem_r-P3" pos="0 0 0"/>
                    </body>
                    <body name="vasti_r_vas_int_r-P4" pos="0 0 0.001799">
                        <inertial diaginertia="0.00000001 0.00000001 0.00000001" mass="0.001" pos="0 0 0.001799"/>
                        <joint axis="1 0 0" name="vasti_r_vas_int_r-P4_x" pos="0 0 0" range="0.008273 0.06844" type="slide"/>
                        <joint axis="0 1 0" name="vasti_r_vas_int_r-P4_y" pos="0 0 0" range="-0.06857 0.02752" type="slide"/>
                        <site name="vasti_r_vas_int_r-P4" pos="0 0 0"/>
                    </body>
                </body>
                <body name="gastroc_r_med_gas_r-P2" pos="0 0 0">
                    <inertial diaginertia="0.00000001 0.00000001 0.00000001" mass="0.001" pos="0 0 0"/>
                    <joint axis="1 0 0" name="gastroc_r_med_gas_r-P2_x" pos="0 0 0" range="-0.03 -0.019" type="slide"/>
                    <joint axis="0 1 0" name="gastroc_r_med_gas_r-P2_y" pos="0 0 0" range="-0.4022 -0.3929" type="slide"/>
                    <joint axis="0 0 1" name="gastroc_r_med_gas_r-P2_z" pos="0 0 0" range="-0.0258 -0.0235" type="slide"/>
                    <site name="gastroc_r_med_gas_r-P2" pos="0 0 0"/>
                </body>
            </body>

            <body name="femur_l" pos="-0.0707 -0.0661 -0.0835">
                <inertial diaginertia="0.1412 0.145 0.0351" mass="9.3014" pos="0 -0.2 0" quat="0.5 0.5 -0.5 0.5"/>
                <joint axis="0 0 1" name="hip_flexion_l" pos="0 0 0" range="-0.349 2.356"/>
                <joint axis="1 0 0" name="hip_adduction_l" pos="0 0 0" range="-0.873 0.524"/>
                <joint axis="0 1 0" name="hip_rotation_l" pos="0 0 0" range="-0.698 0.698"/>
                <geom mesh="femur_l_geom_1_l_femur" name="femur_l_geom_1" rgba="1 1 1 1" type="mesh"/>
                <site name="abd_l_glut_med2_l-P2" pos="-0.0258 -0.0058 -0.0527"/>
                <site name="add_l_add_mag1_l-P2" pos="-0.0045 -0.1211 -0.0339"/>
                <site name="bifemsh_l_bifemsh_l-P1" pos="0.005 -0.2111 -0.0234"/>
                <site name="glut_max_l_glut_max2_l-P3" pos="-0.0426 -0.053 -0.0293"/>
                <site name="glut_max_l_glut_max2_l-P4" pos="-0.0156 -0.1016 -0.0419"/>
                <site name="iliopsoas_l_psoas_l-P4" pos="0.0016 -0.0507 -0.0038"/>
                <site name="iliopsoas_l_psoas_l-P5" pos="-0.0188 -0.0597 -0.0104"/>
                <site name="vasti_l_vas_int_l-P1" pos="0.029 -0.1924 -0.031"/>
                <site name="vasti_l_vas_int_l-P2" pos="0.0335 -0.2084 -0.0285"/>
                <site name="vasti_l_vas_int_l-P3" pos="0.048 -0.35 -0.0055"/>
                <site name="gastroc_l_med_gas_l-P1" pos="-0.019 -0.3929 0.0235"/>
                <site name="rect_fem_l_rect_fem_l-P2" pos="0.048 -0.35 0.0055"/>

                <body name="tibia_l" pos="0 0 0">
                    <inertial diaginertia="0.0511 0.0504 0.0051" mass="3.7075" pos="0 -0.1867 0" quat="0.5 0.5 -0.5 0.5"/>
                    <joint axis="1 0 0" name="knee_l_translation1" pos="0 0 0" range="-0.005574 0.00411" type="slide"/> 
					<joint axis="0 1 0" name="knee_l_translation2" pos="0 0 0" range="-0.4226 -0.3953" type="slide"/>
                    <joint axis="0 0 1" name="knee_angle_l" pos="0 0 0" range="-2.531 0.0"/>
                    <geom mesh="tibia_l_geom_1_l_tibia" name="tibia_l_geom_1" rgba="1 1 1 1" type="mesh"/>
                    <geom mesh="tibia_l_geom_2_l_fibula" name="tibia_l_geom_2" rgba="1 1 1 1" type="mesh"/>
                    <site name="hamstrings_l_semimem_l-P3" pos="-0.027 -0.04771 0.01957"/>
                    <site name="bifemsh_l_bifemsh_l-P2" pos="-0.0301 -0.036 -0.02943"/>
                    <site name="bifemsh_l_bifemsh_l-P3" pos="-0.0234 -0.0563 -0.0343"/>
                    <site name="soleus_l_soleus_l-P1" pos="-0.0024 -0.1533 -0.0071"/>
                    <site name="tib_ant_l_tib_ant_l-P1" pos="0.0179 -0.1624 -0.0115"/>
                    <site name="tib_ant_l_tib_ant_l-P2" pos="0.0329 -0.3951 0.0177"/>
                    <site name="edl_l-P1" pos="-0.016 -0.1157 -0.0205"/>
                    <site name="edl_l-P2" pos="0.0164 -0.376 -0.0112"/>
                    <site name="fdl_l-P1" pos="-0.0023 -0.1832 0.0018"/>
                    <site name="fdl_l-P2" pos="-0.0176 -0.3645 0.0124"/>

                    <body name="talus_l" pos="0 -0.40 0">
                        <inertial diaginertia="0.0001 0.0001 0.0001" mass="0.1" pos="0 0 0"/>
                        <joint axis="0 0 1" name="ankle_angle_l" pos="0 0 0" range="-1.134 0.349"/>
                        <geom mesh="talus_l_geom_1_l_talus" name="talus_l_geom_1" rgba="1 1 1 1" type="mesh"/>

                        <body name="calcn_l" pos="-0.04877 -0.04195 -0.00792">
                            <inertial diaginertia="0.00041 0.00039 0.00014" mass="1.25" pos="0.1 0.03 0" quat="0 0.707107 0 0.707107"/>
                            <geom mesh="calcn_l_geom_1_l_foot" name="calcn_l_geom_1" rgba="1 1 1 1" type="mesh"/>
                            <site name="gastroc_l_med_gas_l-P3" pos="0 0.031 0.0053"/>
                            <site name="soleus_l_soleus_l-P2" pos="0 0.031 0.0053"/>
                            <site name="tib_ant_l_tib_ant_l-P3" pos="0.1166 0.0178 0.0305"/>
                            <site name="edl_l-P3" pos="0.0919 0.036 -0.0008"/>
                            <site name="edl_l-P4" pos="0.1616 0.0055 -0.013"/>
                            <site name="fdl_l-P3" pos="0.0436 0.0315 0.028"/>
                            <site name="fdl_l-P4" pos="0.0708 0.0176 0.0263"/>
                            <site name="fdl_l-P5" pos="0.1658 -0.0081 -0.0116"/>

                            <site name="l_foot_touch" type="box" pos="0.01 -0.002 0.01" size=".03 .02 .03" euler="0 0 0" class="myo_leg_touch"/>
                            <site name="l_heel_btm" type="sphere" pos="0.01 -0.008 0.01" size="0.01" group="3" rgba="0 1 0 0.4"/>
                            <site name="l_toe_btm" type="sphere" pos="0.17 -0.003 0.01" size="0.01" group="3" rgba="0 1 0 0.4"/>

                            <body name="toes_l" pos="0.1788 -0.002 -0.00108">
                                <inertial diaginertia="0.0001 0.0001 0.0001" mass="0.2166" pos="0.0346 0.006 -0.0175" quat="0 0.707107 0 0.707107"/>
                                <joint axis="0 0 1" name="mtp_angle_l" damping= "0.5" pos="0 0 0" range="-0.523599 0.523599"/>
                                <geom mesh="toes_l_geom_1_l_bofoot" name="toes_l_geom_1" rgba="1 1 1 1" type="mesh"/>
								<site name="l_toes_touch" type="box" pos="0.0 -0.002 0.01" size=".05 .025 .075" euler="0 1.5 0" class="myo_leg_touch"/>
                                <site name="edl_l-P5" pos="0.0003 0.0047 -0.0153"/>
                                <site name="edl_l-P6" pos="0.0443 -0.0004 -0.025"/>
                                <site name="fdl_l-P6" pos="-0.0019 -0.0078 -0.0147"/>
                                <site name="fdl_l-P7" pos="0.0285 -0.0071 -0.0215"/>
                                <site name="fdl_l-P8" pos="0.0441 -0.006 -0.0242"/>
                            </body>
                        </body>
                    </body>

                    <body name="hamstrings_l_semimem_l-P2" pos="0 0 0.01891">
                        <inertial diaginertia="0.00000001 0.00000001 0.00000001" mass="0.001" pos="0 0 0.01891"/>
                        <joint axis="1 0 0" name="hamstrings_l_semimem_l-P2_x" pos="0 0 0" range="-0.0348 -0.027" type="slide"/>
                        <joint axis="0 1 0" name="hamstrings_l_semimem_l-P2_y" pos="0 0 0" range="-0.04771 -0.03519" type="slide"/>
                        <site name="hamstrings_l_semimem_l-P2" pos="0 0 0"/>
                    </body>
                    <body name="rect_fem_l_rect_fem_l-P3" pos="0 0 -0.001401">
                        <inertial diaginertia="0.00000001 0.00000001 0.00000001" mass="0.001" pos="0 0 -0.001401"/>
                        <joint axis="1 0 0" name="rect_fem_l_rect_fem_l-P3_x" pos="0 0 0" range="0.01558 0.0733" type="slide"/>
                        <joint axis="0 1 0" name="rect_fem_l_rect_fem_l-P3_y" pos="0 0 0" range="-0.06738 0.02531" type="slide"/>
                        <site name="rect_fem_l_rect_fem_l-P3" pos="0 0 0"/>
                    </body>
                    <body name="vasti_l_vas_int_l-P4" pos="0 0 0.001799">
                        <inertial diaginertia="0.00000001 0.00000001 0.00000001" mass="0.001" pos="0 0 0.001799"/>
                        <joint axis="1 0 0" name="vasti_l_vas_int_l-P4_x" pos="0 0 0" range="0.008273 0.06844" type="slide"/>
                        <joint axis="0 1 0" name="vasti_l_vas_int_l-P4_y" pos="0 0 0" range="-0.06857 0.02752" type="slide"/>
                        <site name="vasti_l_vas_int_l-P4" pos="0 0 0"/>
                    </body>
                </body>
                <body name="gastroc_l_med_gas_l-P2" pos="0 0 0">
                    <inertial diaginertia="0.00000001 0.00000001 0.00000001" mass="0.001" pos="0 0 0"/>
                    <joint axis="1 0 0" name="gastroc_l_med_gas_l-P2_x" pos="0 0 0" range="-0.03 -0.019" type="slide"/>
                    <joint axis="0 1 0" name="gastroc_l_med_gas_l-P2_y" pos="0 0 0" range="-0.4022 -0.3929" type="slide"/>
                    <joint axis="0 0 1" name="gastroc_l_med_gas_l-P2_z" pos="0 0 0" range="-0.0258 -0.0235" type="slide"/>
                    <site name="gastroc_l_med_gas_l-P2" pos="0 0 0"/>
                </body>
            </body>

            <body name="torso" pos="-0.1007 0.0815 0">
                <inertial diaginertia="1.4745 1.4314 0.45" mass="34.2366" pos="0.01 0.325 0" quat="0.707107 0.707107 0 0"/>
                <geom mesh="torso_geom_1_hat_spine" name="torso_geom_1" rgba="1 1 1 1" type="mesh"/>
                <geom mesh="torso_geom_2_hat_jaw" name="torso_geom_2" rgba="1 1 1 1" type="mesh"/>
                <geom mesh="torso_geom_3_hat_skull" name="torso_geom_3" rgba="1 1 1 1" type="mesh"/>
                <geom mesh="torso_geom_4_hat_ribs" name="torso_geom_4" rgba="1 1 1 1" type="mesh"/>

                <body name="r_clavicle" pos="-0.001 0.175 -1.09">
                    <inertial pos="0.01 0.215 1.15" mass="0.156" diaginertia="0.00024259 0.00025526 4.442e-05"/>
                    <geom type="mesh" mesh="r_clavicle" name="r_clavicle_geom" rgba="1 1 1 1"/>
                    
                    <body name="r_scapula" pos="-0.145 0.0725 -0.125">
                        <inertial pos="0.095 0.09 1.35" mass="0.70396" diaginertia="0.0012429 0.0011504 0.0013651"/>
                        <geom type="mesh" mesh="r_scapula" name="r_scapula_geom" rgba="1 1 1 1"/>
                        
                        <body name="r_humerus" pos="0.165 0.12 1.385">
                            <joint name="r_shoulder_abd" type="hinge" pos="0 0 0" axis="-1 0 0" range="-2.0 2.0" damping="10000"/>
                            <joint name="r_shoulder_rot" type="hinge" pos="0 0 0" axis="0 1 0" range="-2.0 2.0" damping="10000"/>
                            <joint name="r_shoulder_flex" type="hinge" pos="0 0 0" axis="0 0 1" range="-1.5 3.0" damping="10000"/>
                            <inertial pos="0.018064 -0.140141 -0.012746" mass="1.99757" diaginertia="0.0122776 0.00255133 0.0125789"/>
                            <geom type="mesh" mesh="r_humerus" name="r_humerus_geom" rgba="1 1 1 1"/>

                            <body name="r_ulna" pos="0 -0.4 -0.035" euler="0.1 0 0">
                                <inertial pos="0 0 0" mass="0.55265" diaginertia="0.00306940 0.00063784 0.00314473"/>
                                <joint name="r_elbow_flex" type="hinge" pos="0.015 0.11 -0.01" axis="0 0 1" range="0 2" damping="10000"/>
                                <geom type="mesh" mesh="r_ulna" name="r_ulna_geom" rgba="1 1 1 1"/>
                                
                                <body name="r_radius" pos="0.0295 -0.015 0.022" euler="0 0 -0.075">
                                    <inertial pos="0 0 0" mass="0.55265" diaginertia="0.00306940 0.00063784 0.00314473"/>
                                    <joint name="r_wrist_rot" type="hinge" pos="-0.025 0.1 -0.005" axis="0 1 0" range="-2 2" damping="10000"/>
                                    <geom type="mesh" mesh="r_radius" name="r_radius_geom" rgba="1 1 1 1"/>

                                    <body name="r_hand" pos="0 -0.2 -0.05">
                                        <joint name="r_wrist_flex" type="hinge" pos="0 0.1 0.075" axis="1 0 0" range="-1.0 1.0" damping="10000"/>
                                        <joint name="r_wrist_dev" type="hinge" pos="0 0.1 0.075" axis="0 0 1" range="-1.0 1.0" damping="10000"/>
                                        <inertial pos="0 0 0.05" mass="0.20" diaginertia="0.0005 0.0005 0.00075"/>
                                        <geom type="mesh" mesh="r_hand" name="r_hand_geom" rgba="1 1 1 1"/>
                                    </body>
                                </body>
                            </body>
                        </body>
                    </body>
                </body>

                <body name="l_clavicle" pos="-0.005 0.175 -1.11">
                    <inertial pos="0.01 0.215 1.05" mass="0.156" diaginertia="0.00024259 0.00025526 4.442e-05"/>
                    <geom type="mesh" mesh="l_clavicle" name="l_clavicle_geom" rgba="1 1 1 1"/>
                    
                    <body name="l_scapula" pos="-0.075 0.0725 -0.375">
                        <inertial pos="0.025 0.09 1.35" mass="0.70396" diaginertia="0.0012429 0.0011504 0.0013651"/>
                        <geom type="mesh" mesh="l_scapula" name="l_scapula_geom" rgba="1 1 1 1"/>
                        
                        <body name="l_humerus" pos="0.095 0.12 1.31">
                            <joint name="l_shoulder_abd" type="hinge" pos="0 0 0" axis="1 0 0" range="-2.0 2.0" damping="10000"/>
                            <joint name="l_shoulder_rot" type="hinge" pos="0 0 0" axis="0 -1 0" range="-2.0 2.0" damping="10000"/>
                            <joint name="l_shoulder_flex" type="hinge" pos="0 0 0" axis="0 0 -1" range="-1.5 3.0" damping="10000"/>
                            <inertial pos="0.018064 -0.140141 -0.012746" mass="1.99757" diaginertia="0.0122776 0.00255133 0.0125789"/>
                            <geom type="mesh" mesh="l_humerus" name="l_humerus_geom" rgba="1 1 1 1"/>
                        
                            <body name="l_ulna" pos="0 -0.405 -0.01" euler="-0.1 0 0">
                                <inertial pos="0 0 0" mass="0.55265" diaginertia="0.00306940 0.00063784 0.00314473"/>
                                <joint name="l_elbow_flex" type="hinge" pos="0.015 0.11 -0.005" axis="0 0 1" range="0 2" damping="10000"/> 
                                <geom type="mesh" mesh="l_ulna" name="l_ulna_geom" rgba="1 1 1 1"/>
                                
                                <body name="l_radius" pos="0.028 -0.015 -0.005" euler="0 0 -0.075">
                                    <inertial pos="0 0 0" mass="0.55265" diaginertia="0.00306940 0.00063784 0.00314473"/>
                                    <joint name="l_wrist_rot" type="hinge" pos="-0.025 0.12 0.025" axis="0 -1 0" range="-2 2" damping="10000"/>
                                    <geom type="mesh" mesh="l_radius" name="l_radius_geom" rgba="1 1 1 1"/>

                                    <body name="l_hand" pos="0.002 -0.195 0.19">
                                        <inertial pos="0 0 -0.165" mass="0.20" diaginertia="0.0005 0.0005 0.00075"/>
                                        <joint name="l_wrist_flex" type="hinge" pos="0 0.1 -0.175" axis="-1 0 0" range="-1.0 1.0" damping="10000"/>
                                        <joint name="l_wrist_dev" type="hinge" pos="0 0.1 -0.175" axis="0 0 1" range="-1.0 1.0" damping="10000"/>
                                        <geom type="mesh" mesh="l_hand" name="l_hand_geom" rgba="1 1 1 1"/>
                                    </body>
                                </body>
                            </body>
                        </body>
                    </body>
                </body>

                <body name="head" pos="0 0.55 0">
                </body>
            </body>

            <body name="iliopsoas_r_psoas_r-P3" pos="0 0 0">
                <inertial diaginertia="0.00000001 0.00000001 0.00000001" mass="0.001" pos="0 0 0"/>
                <joint axis="1 0 0" name="iliopsoas_r_psoas_r-P3_x" pos="0 0 0" range="-0.0288 -0.0238" type="slide"/>
                <joint axis="0 1 0" name="iliopsoas_r_psoas_r-P3_y" pos="0 0 0" range="-0.0805 -0.057" type="slide"/>
                <joint axis="0 0 1" name="iliopsoas_r_psoas_r-P3_z" pos="0 0 0" range="0.0759 0.0816" type="slide"/>
                <site name="iliopsoas_r_psoas_r-P3" pos="0 0 0"/>
            </body>
            <body name="iliopsoas_l_psoas_l-P3" pos="0 0 0">
                <inertial diaginertia="0.00000001 0.00000001 0.00000001" mass="0.001" pos="0 0 0"/>
                <joint axis="1 0 0" name="iliopsoas_l_psoas_l-P3_x" pos="0 0 0" range="-0.0288 -0.0238" type="slide"/>
                <joint axis="0 1 0" name="iliopsoas_l_psoas_l-P3_y" pos="0 0 0" range="-0.0805 -0.057" type="slide"/>
                <joint axis="0 0 1" name="iliopsoas_l_psoas_l-P3_z" pos="0 0 0" range="-0.0816 -0.0759" type="slide"/>
                <site name="iliopsoas_l_psoas_l-P3" pos="0 0 0"/>
            </body>
        </body>
    </worldbody>
    <contact>
        <pair geom1="ground-plane" geom2="pelvis_geom_1"/>
        <pair geom1="ground-plane" geom2="pelvis_geom_2"/>
        <pair geom1="ground-plane" geom2="pelvis_geom_3"/>
        <pair geom1="ground-plane" geom2="femur_r_geom_1"/>
        <pair geom1="ground-plane" geom2="tibia_r_geom_1"/>
        <pair geom1="ground-plane" geom2="tibia_r_geom_2"/>
        <pair geom1="ground-plane" geom2="talus_r_geom_1"/>
        <pair geom1="ground-plane" geom2="calcn_r_geom_1"/>
        <pair geom1="ground-plane" geom2="femur_l_geom_1"/>
        <pair geom1="ground-plane" geom2="tibia_l_geom_1"/>
        <pair geom1="ground-plane" geom2="tibia_l_geom_2"/>
        <pair geom1="ground-plane" geom2="talus_l_geom_1"/>
        <pair geom1="ground-plane" geom2="calcn_l_geom_1"/>
        <pair geom1="ground-plane" geom2="torso_geom_1"/>
        <pair geom1="ground-plane" geom2="torso_geom_2"/>
        <pair geom1="ground-plane" geom2="torso_geom_3"/>
        <pair geom1="ground-plane" geom2="torso_geom_4"/>

        <pair geom1="terrain" geom2="pelvis_geom_1"/>
        <pair geom1="terrain" geom2="pelvis_geom_2"/>
        <pair geom1="terrain" geom2="pelvis_geom_3"/>
        <pair geom1="terrain" geom2="femur_r_geom_1"/>
        <pair geom1="terrain" geom2="tibia_r_geom_1"/>
        <pair geom1="terrain" geom2="tibia_r_geom_2"/>
        <pair geom1="terrain" geom2="talus_r_geom_1"/>
        <pair geom1="terrain" geom2="calcn_r_geom_1"/>
        <pair geom1="terrain" geom2="femur_l_geom_1"/>
        <pair geom1="terrain" geom2="tibia_l_geom_1"/>
        <pair geom1="terrain" geom2="tibia_l_geom_2"/>
        <pair geom1="terrain" geom2="talus_l_geom_1"/>
        <pair geom1="terrain" geom2="calcn_l_geom_1"/>
        <pair geom1="terrain" geom2="torso_geom_1"/>
        <pair geom1="terrain" geom2="torso_geom_2"/>
        <pair geom1="terrain" geom2="torso_geom_3"/>
        <pair geom1="terrain" geom2="torso_geom_4"/>

		<!-- Self collision -->
		<pair geom1="femur_r_geom_1" geom2="femur_l_geom_1"/>
		<pair geom1="femur_r_geom_1" geom2="tibia_l_geom_1"/>
		<pair geom1="femur_r_geom_1" geom2="tibia_l_geom_2"/>
		<pair geom1="femur_r_geom_1" geom2="talus_l_geom_1"/>
		<pair geom1="femur_r_geom_1" geom2="calcn_l_geom_1"/>
		
		<pair geom1="tibia_r_geom_1" geom2="femur_l_geom_1"/>
		<pair geom1="tibia_r_geom_1" geom2="tibia_l_geom_1"/>
		<pair geom1="tibia_r_geom_1" geom2="tibia_l_geom_2"/>
		<pair geom1="tibia_r_geom_1" geom2="talus_l_geom_1"/>
		<pair geom1="tibia_r_geom_1" geom2="calcn_l_geom_1"/>
		
		<pair geom1="tibia_r_geom_2" geom2="femur_l_geom_1"/>
		<pair geom1="tibia_r_geom_2" geom2="tibia_l_geom_1"/>
		<pair geom1="tibia_r_geom_2" geom2="tibia_l_geom_2"/>
		<pair geom1="tibia_r_geom_2" geom2="talus_l_geom_1"/>
		<pair geom1="tibia_r_geom_2" geom2="calcn_l_geom_1"/>
		
		<pair geom1="talus_r_geom_1" geom2="femur_l_geom_1"/>
		<pair geom1="talus_r_geom_1" geom2="tibia_l_geom_1"/>
		<pair geom1="talus_r_geom_1" geom2="tibia_l_geom_2"/>
		<pair geom1="talus_r_geom_1" geom2="talus_l_geom_1"/>
		<pair geom1="talus_r_geom_1" geom2="calcn_l_geom_1"/>
		
		<pair geom1="calcn_r_geom_1" geom2="femur_l_geom_1"/>
		<pair geom1="calcn_r_geom_1" geom2="tibia_l_geom_1"/>
		<pair geom1="calcn_r_geom_1" geom2="tibia_l_geom_2"/>
		<pair geom1="calcn_r_geom_1" geom2="talus_l_geom_1"/>
		<pair geom1="calcn_r_geom_1" geom2="calcn_l_geom_1"/>

    </contact>
    <equality>
        <joint joint1="knee_r_translation1" joint2="knee_angle_r" polycoef="-0.003639 -0.006267 0.002807 0.00134 -0.0006776" solimp="0.9999 0.9999 0.001 0.5 2"/>
        <joint joint1="knee_r_translation2" joint2="knee_angle_r" polycoef="-0.395 0.003413 -0.005587 0.0006697 0.0005674" solimp="0.9999 0.9999 0.001 0.5 2"/>
        <joint joint1="knee_l_translation1" joint2="knee_angle_l" polycoef="-0.003639 -0.006267 0.002807 0.00134 -0.0006776" solimp="0.9999 0.9999 0.001 0.5 2"/>
        <joint joint1="knee_l_translation2" joint2="knee_angle_l" polycoef="-0.395 0.003413 -0.005587 0.0006697 0.0005674" solimp="0.9999 0.9999 0.001 0.5 2"/>
        <joint joint1="hamstrings_r_semimem_r-P2_x" joint2="knee_angle_r" polycoef="-0.03429 -0.005119 0.001791 0.001624 0.0002251" solimp="0.9999 0.9999 0.001 0.5 2"/>
        <joint joint1="hamstrings_r_semimem_r-P2_y" joint2="knee_angle_r" polycoef="-0.03601 0.008217 -0.002875 -0.002607 -0.0003613" solimp="0.9999 0.9999 0.001 0.5 2"/>
        <joint joint1="iliopsoas_r_psoas_r-P3_x" joint2="hip_flexion_r" polycoef="-0.02855 0.001773 0.001122 -0.0001037 -0.0001111" solimp="0.9999 0.9999 0.001 0.5 2"/>
        <joint joint1="iliopsoas_r_psoas_r-P3_y" joint2="hip_flexion_r" polycoef="-0.07933 0.008332 0.005272 -0.0004875 -0.0005223" solimp="0.9999 0.9999 0.001 0.5 2"/>
        <joint joint1="iliopsoas_r_psoas_r-P3_z" joint2="hip_flexion_r" polycoef="0.08132 -0.002021 -0.001279 0.0001182 0.0001267" solimp="0.9999 0.9999 0.001 0.5 2"/>
        <joint joint1="rect_fem_r_rect_fem_r-P3_x" joint2="knee_angle_r" polycoef="0.06259 0.04199 0.01152 -0.007248 -0.004008" solimp="0.9999 0.9999 0.001 0.5 2"/>
        <joint joint1="rect_fem_r_rect_fem_r-P3_y" joint2="knee_angle_r" polycoef="0.02032 -0.01159 -0.008624 -0.002308 -0.0002292" solimp="0.9999 0.9999 0.001 0.5 2"/>
        <joint joint1="vasti_r_vas_int_r-P4_x" joint2="knee_angle_r" polycoef="0.05647 0.04555 0.01393 -0.007247 -0.004235" solimp="0.9999 0.9999 0.001 0.5 2"/>
        <joint joint1="vasti_r_vas_int_r-P4_y" joint2="knee_angle_r" polycoef="0.02476 -0.006322 -0.00661 -0.003684 -0.0008973" solimp="0.9999 0.9999 0.001 0.5 2"/>
        <joint joint1="gastroc_r_med_gas_r-P2_x" joint2="knee_angle_r" polycoef="-0.02607 0.00676 0.0009439 -0.001031 -6.818e-05" solimp="0.9999 0.9999 0.001 0.5 2"/>
        <joint joint1="gastroc_r_med_gas_r-P2_y" joint2="knee_angle_r" polycoef="-0.3989 0.005715 0.000798 -0.000872 -5.764e-05" solimp="0.9999 0.9999 0.001 0.5 2"/>
        <joint joint1="gastroc_r_med_gas_r-P2_z" joint2="knee_angle_r" polycoef="-0.02498 0.001413 0.0001974 -0.0002157 -1.426e-05" solimp="0.9999 0.9999 0.001 0.5 2"/>
        <joint joint1="hamstrings_l_semimem_l-P2_x" joint2="knee_angle_l" polycoef="-0.03429 -0.005119 0.001791 0.001624 0.0002251" solimp="0.9999 0.9999 0.001 0.5 2"/>
        <joint joint1="hamstrings_l_semimem_l-P2_y" joint2="knee_angle_l" polycoef="-0.03601 0.008217 -0.002875 -0.002607 -0.0003613" solimp="0.9999 0.9999 0.001 0.5 2"/>
        <joint joint1="iliopsoas_l_psoas_l-P3_x" joint2="hip_flexion_l" polycoef="-0.02855 0.001773 0.001122 -0.0001037 -0.0001111" solimp="0.9999 0.9999 0.001 0.5 2"/>
        <joint joint1="iliopsoas_l_psoas_l-P3_y" joint2="hip_flexion_l" polycoef="-0.07933 0.008332 0.005272 -0.0004875 -0.0005223" solimp="0.9999 0.9999 0.001 0.5 2"/>
        <joint joint1="iliopsoas_l_psoas_l-P3_z" joint2="hip_flexion_l" polycoef="-0.08132 0.002021 0.001279 -0.0001182 -0.0001267" solimp="0.9999 0.9999 0.001 0.5 2"/>
        <joint joint1="rect_fem_l_rect_fem_l-P3_x" joint2="knee_angle_l" polycoef="0.06259 0.04199 0.01152 -0.007248 -0.004008" solimp="0.9999 0.9999 0.001 0.5 2"/>
        <joint joint1="rect_fem_l_rect_fem_l-P3_y" joint2="knee_angle_l" polycoef="0.02032 -0.01159 -0.008624 -0.002308 -0.0002292" solimp="0.9999 0.9999 0.001 0.5 2"/>
        <joint joint1="vasti_l_vas_int_l-P4_x" joint2="knee_angle_l" polycoef="0.05647 0.04555 0.01393 -0.007247 -0.004235" solimp="0.9999 0.9999 0.001 0.5 2"/>
        <joint joint1="vasti_l_vas_int_l-P4_y" joint2="knee_angle_l" polycoef="0.02476 -0.006322 -0.00661 -0.003684 -0.0008973" solimp="0.9999 0.9999 0.001 0.5 2"/>
        <joint joint1="gastroc_l_med_gas_l-P2_x" joint2="knee_angle_l" polycoef="-0.02607 0.00676 0.0009439 -0.001031 -6.818e-05" solimp="0.9999 0.9999 0.001 0.5 2"/>
        <joint joint1="gastroc_l_med_gas_l-P2_y" joint2="knee_angle_l" polycoef="-0.3989 0.005715 0.000798 -0.000872 -5.764e-05" solimp="0.9999 0.9999 0.001 0.5 2"/>
        <joint joint1="gastroc_l_med_gas_l-P2_z" joint2="knee_angle_l" polycoef="0.02498 -0.001413 -0.0001974 0.0002157 1.426e-05" solimp="0.9999 0.9999 0.001 0.5 2"/>
    </equality>
	
    <sensor>
        <touch name="r_foot" site="r_foot_touch"/>
        <touch name="r_toes" site="r_toes_touch"/>
        <touch name="l_foot" site="l_foot_touch"/>
        <touch name="l_toes" site="l_toes_touch"/>
		<jointlimitfrc name="r_knee_sensor" joint="knee_angle_r"/>
		<jointlimitfrc name="l_knee_sensor" joint="knee_angle_l"/>
		<jointlimitfrc name="r_hip_sensor" joint="hip_flexion_r"/>
		<jointlimitfrc name="l_hip_sensor" joint="hip_flexion_l"/>
		<jointlimitfrc name="r_ankle_sensor" joint="ankle_angle_r"/>
		<jointlimitfrc name="l_ankle_sensor" joint="ankle_angle_l"/>
		<jointlimitfrc name="r_mtp_sensor" joint="mtp_angle_r"/>
		<jointlimitfrc name="l_mtp_sensor" joint="mtp_angle_l"/>
    </sensor>
	
    <tendon>
        <spatial name="abd_r_tendon">
            <site site="abd_r_glut_med2_r-P1"/>
            <site site="abd_r_glut_med2_r-P2"/>
        </spatial>
        <spatial name="add_r_tendon">
            <site site="add_r_add_mag1_r-P1"/>
            <site site="add_r_add_mag1_r-P2"/>
        </spatial>
        <spatial name="hamstrings_r_tendon">
            <site site="hamstrings_r_semimem_r-P1"/>
            <site site="hamstrings_r_semimem_r-P2"/>
            <site site="hamstrings_r_semimem_r-P3"/>
        </spatial>
        <spatial name="bifemsh_r_tendon">
            <site site="bifemsh_r_bifemsh_r-P1"/>
            <site site="bifemsh_r_bifemsh_r-P2"/>
            <site site="bifemsh_r_bifemsh_r-P3"/>
        </spatial>
        <spatial name="glut_max_r_tendon">
            <site site="glut_max_r_glut_max2_r-P1"/>
            <site site="glut_max_r_glut_max2_r-P2"/>
            <site site="glut_max_r_glut_max2_r-P3"/>
            <site site="glut_max_r_glut_max2_r-P4"/>
        </spatial>
        <spatial name="iliopsoas_r_tendon">
            <site site="iliopsoas_r_psoas_r-P1"/>
            <site site="iliopsoas_r_psoas_r-P2"/>
            <site site="iliopsoas_r_psoas_r-P3"/>
            <site site="iliopsoas_r_psoas_r-P4"/>
            <site site="iliopsoas_r_psoas_r-P5"/>
        </spatial>
        <spatial name="rect_fem_r_tendon">
            <site site="rect_fem_r_rect_fem_r-P1"/>
            <site site="rect_fem_r_rect_fem_r-P2"/>
            <site site="rect_fem_r_rect_fem_r-P3"/>
        </spatial>
        <spatial name="vasti_r_tendon">
            <site site="vasti_r_vas_int_r-P1"/>
            <site site="vasti_r_vas_int_r-P2"/>
            <site site="vasti_r_vas_int_r-P3"/>
            <site site="vasti_r_vas_int_r-P4"/>
        </spatial>
        <spatial name="gastroc_r_tendon">
            <site site="gastroc_r_med_gas_r-P1"/>
            <site site="gastroc_r_med_gas_r-P2"/>
            <site site="gastroc_r_med_gas_r-P3"/>
        </spatial>
        <spatial name="soleus_r_tendon">
            <site site="soleus_r_soleus_r-P1"/>
            <site site="soleus_r_soleus_r-P2"/>
        </spatial>
        <spatial name="tib_ant_r_tendon">
            <site site="tib_ant_r_tib_ant_r-P1"/>
            <site site="tib_ant_r_tib_ant_r-P2"/>
            <site site="tib_ant_r_tib_ant_r-P3"/>
        </spatial>
        <spatial name="abd_l_tendon">
            <site site="abd_l_glut_med2_l-P1"/>
            <site site="abd_l_glut_med2_l-P2"/>
        </spatial>
        <spatial name="add_l_tendon">
            <site site="add_l_add_mag1_l-P1"/>
            <site site="add_l_add_mag1_l-P2"/>
        </spatial>
        <spatial name="hamstrings_l_tendon">
            <site site="hamstrings_l_semimem_l-P1"/>
            <site site="hamstrings_l_semimem_l-P2"/>
            <site site="hamstrings_l_semimem_l-P3"/>
        </spatial>
        <spatial name="bifemsh_l_tendon">
            <site site="bifemsh_l_bifemsh_l-P1"/>
            <site site="bifemsh_l_bifemsh_l-P2"/>
            <site site="bifemsh_l_bifemsh_l-P3"/>
        </spatial>
        <spatial name="glut_max_l_tendon">
            <site site="glut_max_l_glut_max2_l-P1"/>
            <site site="glut_max_l_glut_max2_l-P2"/>
            <site site="glut_max_l_glut_max2_l-P3"/>
            <site site="glut_max_l_glut_max2_l-P4"/>
        </spatial>
        <spatial name="iliopsoas_l_tendon">
            <site site="iliopsoas_l_psoas_l-P1"/>
            <site site="iliopsoas_l_psoas_l-P2"/>
            <site site="iliopsoas_l_psoas_l-P3"/>
            <site site="iliopsoas_l_psoas_l-P4"/>
            <site site="iliopsoas_l_psoas_l-P5"/>
        </spatial>
        <spatial name="rect_fem_l_tendon">
            <site site="rect_fem_l_rect_fem_l-P1"/>
            <site site="rect_fem_l_rect_fem_l-P2"/>
            <site site="rect_fem_l_rect_fem_l-P3"/>
        </spatial>
        <spatial name="vasti_l_tendon">
            <site site="vasti_l_vas_int_l-P1"/>
            <site site="vasti_l_vas_int_l-P2"/>
            <site site="vasti_l_vas_int_l-P3"/>
            <site site="vasti_l_vas_int_l-P4"/>
        </spatial>
        <spatial name="gastroc_l_tendon">
            <site site="gastroc_l_med_gas_l-P1"/>
            <site site="gastroc_l_med_gas_l-P2"/>
            <site site="gastroc_l_med_gas_l-P3"/>
        </spatial>
        <spatial name="soleus_l_tendon">
            <site site="soleus_l_soleus_l-P1"/>
            <site site="soleus_l_soleus_l-P2"/>
        </spatial>
        <spatial name="tib_ant_l_tendon">
            <site site="tib_ant_l_tib_ant_l-P1"/>
            <site site="tib_ant_l_tib_ant_l-P2"/>
            <site site="tib_ant_l_tib_ant_l-P3"/>
        </spatial>

        <spatial name="edl_r_tendon" springlength="0.368875">
            <site site="edl_r-P1"/>
            <site site="edl_r-P2"/>
            <site site="edl_r-P3"/>
            <site site="edl_r-P4"/>
            <site site="edl_r-P5"/>
            <site site="edl_r-P6"/>
        </spatial>
        <spatial name="fdl_r_tendon" springlength="0.378773">
            <site site="fdl_r-P1"/>
            <site site="fdl_r-P2"/>
            <site site="fdl_r-P3"/>
            <site site="fdl_r-P4"/>
            <site site="fdl_r-P5"/>
            <site site="fdl_r-P6"/>
            <site site="fdl_r-P7"/>
            <site site="fdl_r-P8"/>
        </spatial>

        <spatial name="edl_l_tendon" springlength="0.368875">
            <site site="edl_l-P1"/>
            <site site="edl_l-P2"/>
            <site site="edl_l-P3"/>
            <site site="edl_l-P4"/>
            <site site="edl_l-P5"/>
            <site site="edl_l-P6"/>
        </spatial>
        <spatial name="fdl_l_tendon" springlength="0.378773">
            <site site="fdl_l-P1"/>
            <site site="fdl_l-P2"/>
            <site site="fdl_l-P3"/>
            <site site="fdl_l-P4"/>
            <site site="fdl_l-P5"/>
            <site site="fdl_l-P6"/>
            <site site="fdl_l-P7"/>
            <site site="fdl_l-P8"/>
        </spatial>
    </tendon>

    <actuator>
        <general biasprm="0.169813 1.23281 4323.26 1 0 1.8 10 0.672684 1.4 0" class="muscle" gainprm="0.169813 1.23281 4323.26 1 0 1.8 10 0.672684 1.4 0" lengthrange="0.053712 0.169892" name="abd_r" tendon="abd_r_tendon"/>
        <general biasprm="0.160259 1.33948 3871.82 1 0 1.8 10 1.31477 1.4 0" class="muscle" gainprm="0.160259 1.33948 3871.82 1 0 1.8 10 1.31477 1.4 0" lengthrange="0.0502179 0.203072" name="add_r" tendon="add_r_tendon"/>
        <general biasprm="0.105801 1.56953 3948.49 1 0 1.8 10 1.35553 1.4 0" class="muscle" gainprm="0.105801 1.56953 3948.49 1 0 1.8 10 1.35553 1.4 0" lengthrange="0.321987 0.509548" name="hamstrings_r" tendon="hamstrings_r_tendon"/>
        <general biasprm="0.677513 1.24807 509.424 1 0 1.8 10 0.93595 1.4 0" class="muscle" gainprm="0.677513 1.24807 509.424 1 0 1.8 10 0.93595 1.4 0" lengthrange="0.191264 0.249268" name="bifemsh_r" tendon="bifemsh_r_tendon"/>
        <general biasprm="0.620259 1.40474 553.241 1 0.319949 3.12081 10 1.35486 1.4 0" class="muscle" gainprm="0.620259 1.40474 818.778 1 0.319949 3.12081 10 1.35486 1.4 0" lengthrange="0.411859 0.466224" name="edl_r" tendon="edl_r_tendon"/>
        <general biasprm="0.598501 1.22918 332.13 1 0.357129 3.24643 10 1.8954 1.4 0" class="muscle" gainprm="0.598501 1.22918 1081.909 1 0.357129 3.24643 10 1.8954 1.4 0" lengthrange="0.405466 0.433594" name="fdl_r" tendon="fdl_r_tendon"/>
        <general biasprm="0.620098 1.41881 3276.04 1 0 1.8 10 0.78169 1.4 0" class="muscle" gainprm="0.620098 1.41881 3276.04 1 0 1.8 10 0.78169 1.4 0" lengthrange="0.143998 0.277296" name="glutmax_r" tendon="glut_max_r_tendon"/>
        <general biasprm="0.537695 1.29267 2585.58 1 0 1.8 10 0.767706 1.4 0" class="muscle" gainprm="0.537695 1.29267 2585.58 1 0 1.8 10 0.767706 1.4 0" lengthrange="0.191629 0.297306" name="iliopsoas_r" tendon="iliopsoas_r_tendon"/>
        <general biasprm="0.112356 1.37774 1800.5 1 0 1.8 10 0.394414 1.4 0" class="muscle" gainprm="0.112356 1.37774 1800.5 1 0 1.8 10 0.394414 1.4 0" lengthrange="0.32136 0.510234" name="rectfem_r" tendon="rect_fem_r_tendon"/>
        <general biasprm="0.689617 1.52507 9500.94 1 0 1.8 10 0.440576 1.4 0" class="muscle" gainprm="0.689617 1.52507 9500.94 1 0 1.8 10 0.440576 1.4 0" lengthrange="0.174556 0.258507" name="vasti_r" tendon="vasti_r_tendon"/>
        <general biasprm="0.111359 1.10082 3820.44 1 0 1.8 10 1.28141 1.4 0" class="muscle" gainprm="0.111359 1.10082 3820.44 1 0 1.8 10 1.28141 1.4 0" lengthrange="0.362049 0.489534" name="gastroc_r" tendon="gastroc_r_tendon"/>
        <general biasprm="0.123627 1.18435 6090 1 0 1.8 10 1.44603 1.4 0" class="muscle" gainprm="0.123627 1.18435 6090 1 0 1.8 10 1.44603 1.4 0" lengthrange="0.228134 0.326673" name="soleus_r" tendon="soleus_r_tendon"/>
        <general biasprm="0.34957 1.29783 2042.4 1 0 1.8 10 0.972121 1.4 0" class="muscle" gainprm="0.34957 1.29783 2042.4 1 0 1.8 10 0.972121 1.4 0" lengthrange="0.259564 0.352614" name="tibant_r" tendon="tib_ant_r_tendon"/>
		
        <general biasprm="0.169813 1.23281 4323.26 1 0 1.8 10 0.672684 1.4 0" class="muscle" gainprm="0.169813 1.23281 4323.26 1 0 1.8 10 0.672684 1.4 0" lengthrange="0.053712 0.169892" name="abd_l" tendon="abd_l_tendon"/>
        <general biasprm="0.160259 1.33948 3871.82 1 0 1.8 10 1.31477 1.4 0" class="muscle" gainprm="0.160259 1.33948 3871.82 1 0 1.8 10 1.31477 1.4 0" lengthrange="0.0502179 0.203072" name="add_l" tendon="add_l_tendon"/>
        <general biasprm="0.105801 1.56953 3948.49 1 0 1.8 10 1.35553 1.4 0" class="muscle" gainprm="0.105801 1.56953 3948.49 1 0 1.8 10 1.35553 1.4 0" lengthrange="0.321987 0.509548" name="hamstrings_l" tendon="hamstrings_l_tendon"/>
        <general biasprm="0.677513 1.24807 509.424 1 0 1.8 10 0.93595 1.4 0" class="muscle" gainprm="0.677513 1.24807 509.424 1 0 1.8 10 0.93595 1.4 0" lengthrange="0.191264 0.249268" name="bifemsh_l" tendon="bifemsh_l_tendon"/>
        <general biasprm="0.620259 1.40474 553.241 1 0.319949 3.12081 10 1.35486 1.4 0" class="muscle" gainprm="0.620259 1.40474 818.778 1 0.319949 3.12081 10 1.35486 1.4 0" lengthrange="0.411859 0.466224" name="edl_l" tendon="edl_l_tendon"/>
        <general biasprm="0.598501 1.22918 332.13 1 0.357129 3.24643 10 1.8954 1.4 0" class="muscle" gainprm="0.598501 1.22918 1081.909 1 0.357129 3.24643 10 1.8954 1.4 0" lengthrange="0.405466 0.433594" name="fdl_l" tendon="fdl_l_tendon"/>
        <general biasprm="0.620098 1.41881 3276.04 1 0 1.8 10 0.78169 1.4 0" class="muscle" gainprm="0.620098 1.41881 3276.04 1 0 1.8 10 0.78169 1.4 0" lengthrange="0.143998 0.277296" name="glutmax_l" tendon="glut_max_l_tendon"/>
        <general biasprm="0.537695 1.29267 2585.58 1 0 1.8 10 0.767706 1.4 0" class="muscle" gainprm="0.537695 1.29267 2585.58 1 0 1.8 10 0.767706 1.4 0" lengthrange="0.191629 0.297306" name="iliopsoas_l" tendon="iliopsoas_l_tendon"/>
        <general biasprm="0.112356 1.37774 1800.5 1 0 1.8 10 0.394414 1.4 0" class="muscle" gainprm="0.112356 1.37774 1800.5 1 0 1.8 10 0.394414 1.4 0" lengthrange="0.32136 0.510234" name="rectfem_l" tendon="rect_fem_l_tendon"/>
        <general biasprm="0.689617 1.52507 9500.94 1 0 1.8 10 0.440576 1.4 0" class="muscle" gainprm="0.689617 1.52507 9500.94 1 0 1.8 10 0.440576 1.4 0" lengthrange="0.174556 0.258507" name="vasti_l" tendon="vasti_l_tendon"/>
        <general biasprm="0.111359 1.10082 3820.44 1 0 1.8 10 1.28141 1.4 0" class="muscle" gainprm="0.111359 1.10082 3820.44 1 0 1.8 10 1.28141 1.4 0" lengthrange="0.362049 0.489534" name="gastroc_l" tendon="gastroc_l_tendon"/>
        <general biasprm="0.123627 1.18435 6090 1 0 1.8 10 1.44603 1.4 0" class="muscle" gainprm="0.123627 1.18435 6090 1 0 1.8 10 1.44603 1.4 0" lengthrange="0.228134 0.326673" name="soleus_l" tendon="soleus_l_tendon"/>
        <general biasprm="0.34957 1.29783 2042.4 1 0 1.8 10 0.972121 1.4 0" class="muscle" gainprm="0.34957 1.29783 2042.4 1 0 1.8 10 0.972121 1.4 0" lengthrange="0.259564 0.352614" name="tibant_l" tendon="tib_ant_l_tendon"/>
    </actuator>

    <keyframe>
        <key name="stand" qpos="0 0.91 0 0 0 0 0 0 0 0.00411 -0.395 0 -0.0143 0 -0.033 -0.038 0.055 0.022 0.049 0.026 -0.027 -0.4 -0.025 0 0 0 0.00411 -0.395 0 -0.0143 0 -0.033 -0.038 0.055 0.022 0.048 0.026 -0.027 -0.4 0.025 0.12 0 0 0 0 0 0 0.11 0 0 0 0 0 0 0 0 0 0 0 0" qvel="0.0 0.0 0.0 0.0 0.0 0.0 0.0 0.0 0.0 0.0 0.0 0.0 0.0 0.0 0.0 0.0 0.0 0.0 0.0 0.0 0.0 0.0 0.0 0.0 0.0 0.0 0.0 0.0 0.0 0.0 0.0 0.0 0.0 0.0 0.0 0.0 0.0 0.0 0.0 0.0 0.0 0.0 0.0 0.0 0.0 0.0 0.0 0.0 0.0 0.0 0.0 0.0 0.0 0.0 0.0 0.0 0.0 0.0 0.0 0.0" time="0.0"/>

		<key name="walk_left" qpos="0 0.88 0.0 -0.262 0.0 0.0 -0.174 0.0 0.0 0.00411 -0.395 -0.436 0.0 0 -0.033 -0.038 0.055 0.022 0.049 0.026 -0.027 -0.4 -0.025 0.436 0 0 0.00411 -0.395 -0.0873 -0.0737 0 -0.033 -0.038 0.055 0.022 0.048 0.026 -0.027 -0.4 0.025 0.12 0 0 0 0 0 0 0.11 0 0 0 0 0 0 0 0 0 0 0 0" qvel="1.5 0.0 0.0 0.0 0.0 0.0 0.0 0.0 0.0 0.0 0.0 0.0 0.0 0.0 0.0 0.0 0.0 0.0 0.0 0.0 0.0 0.0 0.0 0.0 0.0 0.0 0.0 0.0 0.0 0.0 0.0 0.0 0.0 0.0 0.0 0.0 0.0 0.0 0.0 0.0 0.0 0.0 0.0 0.0 0.0 0.0 0.0 0.0 0.0 0.0 0.0 0.0 0.0 0.0 0.0 0.0 0.0 0.0 0.0 0.0" time="0.0"/>
		
        <key name="walk_right" qpos="0 0.88 0.0 -0.262 0.0 0.0 0.436 0.0 0 0.00411 -0.395 -0.0873 -0.0737 0 -0.033 -0.038 0.055 0.022 0.049 0.026 -0.027 -0.4 -0.025 -0.174 0 0 0.00411 -0.395 -0.436 0 0 -0.033 -0.038 0.055 0.022 0.048 0.026 -0.027 -0.4 0.025 0.12 0 0 0 0 0 0 0.11 0 0 0 0 0 0 0 0 0 0 0 0" qvel="1.5 0.0 0.0 0.0 0.0 0.0 0.0 0.0 0.0 0.0 0.0 0.0 0.0 0.0 0.0 0.0 0.0 0.0 0.0 0.0 0.0 0.0 0.0 0.0 0.0 0.0 0.0 0.0 0.0 0.0 0.0 0.0 0.0 0.0 0.0 0.0 0.0 0.0 0.0 0.0 0.0 0.0 0.0 0.0 0.0 0.0 0.0 0.0 0.0 0.0 0.0 0.0 0.0 0.0 0.0 0.0 0.0 0.0 0.0 0.0" time="0.0"/>
		
		<key name="squat" qpos="0.0 0.72 0.0 -0.611 0.0 0.0 1.309 0.0 0.0 0.00411 -0.395 -1.309 0.349 0.125 -0.0325 -0.0388 0.0529 0.0223 0.0394 0.0293 -0.0274 -0.4 -0.025 1.309 0 0 0.00411 -0.395 -1.309 0.349 0.125 -0.0325 -0.0388 0.0529 0.0223 0.0394 0.0293 -0.0274 -0.4 -0.025 0.12 0 0 0 0 0 0 0.11 0 0 0 0 0 0 0 0 0 0 0 0" qvel="0.0 0.0 0.0 0.0 0.0 0.0 0.0 0.0 0.0 0.0 0.0 0.0 0.0 0.0 0.0 0.0 0.0 0.0 0.0 0.0 0.0 0.0 0.0 0.0 0.0 0.0 0.0 0.0 0.0 0.0 0.0 0.0 0.0 0.0 0.0 0.0 0.0 0.0 0.0 0.0 0.0 0.0 0.0 0.0 0.0 0.0 0.0 0.0 0.0 0.0 0.0 0.0 0.0 0.0 0.0 0.0 0.0 0.0 0.0 0.0" time="0.0"/>
		
		<key name="lunge" qpos="0.0 0.67 0.0 -0.558 0.0 0.0 0.698 0.0 0.0 0.00411 -0.395 -1.48 0.349 0.2 -0.033 -0.038 0.055 0.022 0.049 0.026 -0.027 -0.4 -0.025 1.57 0 0 0.00411 -0.395 -1.222 0.174 0.06 -0.033 -0.038 0.055 0.022 0.048 0.026 -0.027 -0.4 0.025 0.12 0 0 0 0 0 0 0.11 0 0 0 0 0 0 0 0 0 0 0 0" qvel="0.0 0.0 0.0 0.0 0.0 0.0 0.0 0.0 0.0 0.0 0.0 0.0 0.0 0.0 0.0 0.0 0.0 0.0 0.0 0.0 0.0 0.0 0.0 0.0 0.0 0.0 0.0 0.0 0.0 0.0 0.0 0.0 0.0 0.0 0.0 0.0 0.0 0.0 0.0 0.0 0.0 0.0 0.0 0.0 0.0 0.0 0.0 0.0 0.0 0.0 0.0 0.0 0.0 0.0 0.0 0.0 0.0 0.0 0.0 0.0" time="0.0"/>
	</keyframe>

</mujoco>